<mujoco model="Stoupento">
	<compiler angle="radian" />
	<size njmax="500" nconmax="100" />

	<asset>
		<texture builtin="gradient" height="256" rgb1=".9 .9 1." rgb2=".2 .3 .4" type="skybox" width="256" />
		<texture builtin="checker" height="512" name="texplane" rgb1=".2 .3 .4" rgb2=".1 0.15 0.2" type="2d" width="512" />
		<material name="floorplane" reflectance="0.5" texrepeat="1 1" texture="texplane" texuniform="true" />

		<!-- <texture builtin="gradient" height="100" rgb1="1 1 1" rgb2="0 0 0" type="skybox" width="100"/> -->
		<texture builtin="flat" height="1278" mark="cross" markrgb="1 1 1" name="texgeom" random="0.01" rgb1="0.8 0.6 0.4" rgb2="0.8 0.6 0.4" type="cube" width="127" />
		<!-- <texture builtin="checker" height="100" name="texplane" rgb1="0 0 0" rgb2="0.8 0.8 0.8" type="2d" width="100"/> -->
		<texture type="skybox" builtin="gradient" rgb1="0.44 0.85 0.56" rgb2="0.46 0.87 0.58" width="32" height="32"></texture>
		<!-- <texture name="texture_block" file="block.png" gridsize="3 4" gridlayout=".U..LFRB.D.."></texture> -->

		<material name="floor_mat" specular="0" shininess="0.5" reflectance="0" rgba="0.2 0.2 0.2 1"></material>
		<material name="table_mat" specular="0" shininess="0.5" reflectance="0" rgba="0.93 0.93 0.93 1"></material>
		<material name="block_mat" specular="0" shininess="0.5" reflectance="0" rgba="0.2 0.2 0.2 1"></material>
		<material name="puck_mat" specular="0" shininess="0.5" reflectance="0" rgba="0.2 0.2 0.2 1"></material>
		<material name="MatPlane" reflectance="0.5" shininess="1" specular="1" texrepeat="60 60" texture="texplane" />

		<!-- Ramp Mesh -->
		<!-- <mesh file="/home/bmsit/Ascento/Ramp/Ramp.stl" scale="0.3 0.2 0.4"/> -->
		<!-- Terrain -->
		<hfield name="terrain" ncol="201" nrow="201" size="30 30 1 0.1"/>
	</asset>

	<worldbody>
		<geom name='floor' pos='0 0 0' size='10 10 0.125' type='plane' material='floor_mat' condim='3' conaffinity='15'/>
        <!-- <geom name='ramp_up' pos='2 1.2 0' quat="0.9914 0 -0.1306 0" size='1 1 0.00001' type='box' material='table_mat' />
		<geom name='ramp_up_back' pos='-2 1.2 0' quat="0.9914 0 0.1306 0" size='1 1 0.00001' type='box' material='table_mat' />
        <geom name='ramp_straight_back' pos='-2 1.2 0' size='0.5 1 0.00001' type='box' material='table_mat' /> -->
        <!-- <geom name='ramp_down' pos='-2 1 0' euler="0 0.27 0" size='1 1 0.00001' type='box' material='table_mat' /> -->
        <light mode='trackcom' pos='0 0 5' dir='0 0 -1'/>
        <light directional='true' pos='0 0 3' dir='0 0 -1' diffuse='0.2 0.2 0.2' specular='0 0 0'/>

		<!-- <geom name='bump_1' pos='-2 0 0' euler="1.57 0 0" size='0.05 2' type='cylinder' material='table_mat' />
        <geom name='bump_2' pos='-4 0 0' euler="1.57 0 0" size='0.07 2' type='cylinder' material='table_mat' />
        <geom name='bump_3' pos='-6 0 0' euler="1.57 0 0" size='0.09 2' type='cylinder' material='table_mat' />
        <geom name='bump_4' pos='-8 0 0' euler="1.57 0 0" size='0.11 2' type='cylinder' material='table_mat' /> -->
        <!-- <geom name='bump_5' pos='-10 0 0' euler="1.57 0 0" size='0.13 2' type='cylinder' material='table_mat' /> -->
		<!--Terrain-->
		<!-- <geom name="terrain" type="hfield" hfield="terrain" rgba=".2 .3. 4 1" pos="0 0 0"/> -->

		<body name="body" pos="0 0 0" euler="0 0 3.14">

			<joint name="base_com" type="free" />
			<!--geom size="0.25 0.25 0.25" pos="0 0 1" type="box" rgba="0.9 0 0 1" /-0.02578-->
			<geom size="0.125 0.125 0.09" pos="0 0 0.35953" type="box" rgba="1 0 0 1" />
			<inertial pos="0 0 0.35953" mass="1" diaginertia="0.007908 0.007908 0.010417" />

			<body name="Stoupento__right_link2" pos="-0.02133 0.125 0.30973" quat="-0.293145 1.65745e-06 0.956068 1.65745e-06">
				<inertial pos="-0.094 0.005 0" quat="0.5 0.5 0.5 0.5" mass="0.2" diaginertia="0.000604067 0.000590733 1.66667e-05" />
				<joint name="Stoupento__link2_bodyR" pos="0 0 0" axis="0 1 0" />
				<geom size="0.094 0.005 0.015" pos="-0.094 0.005 0" type="box" rgba="0 0 0 1" />
				<body name="Stoupento__right_link1" pos="-0.188 0.015 -0.06" quat="0.636703 1.78329e-07 0.771109 1.78329e-07">
					<inertial pos="-0.12 0.005 0" quat="0.5 0.5 0.5 0.5" mass="0.2" diaginertia="0.000975 0.000961667 1.66667e-05" />
					<joint name="Stoupento__link1_link2R" pos="-0.06 0 0" axis="0 1 0" damping="0.5" />
					<geom size="0.12 0.005 0.015" pos="-0.12 0.005 0" type="box" rgba="0 0 0 1" />
					<body name="Stoupento__right_wheel" pos="-0.24 0.025 0" quat="0.653285 0.653281 0.270596 -0.270595">
						<inertial pos="0 0 0" quat="0.5 0.5 -0.5 0.5" mass="0.3" diaginertia="0.000735 0.00039 0.00039" />
						<joint name="Stoupento__wheel_link1R" pos="0 0 0" axis="0 0 1"/>
						<geom size="0.07 0.015" type="cylinder" rgba="0.8 0 0 1" />
					</body>
				</body>
			</body>
			<body name="Stoupento__left_link2" pos="-0.02133 -0.125 0.30973" quat="-0.293145 1.65745e-06 0.956068 1.65745e-06">
				<inertial pos="-0.094 -0.005 0" quat="0.5 0.5 0.5 0.5" mass="0.2" diaginertia="0.000604067 0.000590733 1.66667e-05" />
				<joint name="Stoupento__link2_bodyL" pos="0 0 0" axis="0 1 0" />
				<geom size="0.094 0.005 0.015" pos="-0.094 -0.005 0" type="box" rgba="0 0 0 1" />
				<body name="Stoupento__left_link1" pos="-0.188 -0.01 -0.06" quat="0.636703 1.78329e-07 0.771109 1.78329e-07">
					<inertial pos="-0.12 -0.005 0" quat="0.5 0.5 0.5 0.5" mass="0.2" diaginertia="0.000975 0.000961667 1.66667e-05" />
					<joint name="Stoupento__link1_link2L" pos="-0.06 0 0" axis="0 -1 0" damping="0.5" />
					<geom size="0.12 0.005 0.015" pos="-0.12 -0.005 0" type="box" rgba="0 0 0 1" />
					<body name="Stoupento__left_wheel" pos="-0.24 -0.025 0" quat="0.653285 0.653281 0.270596 -0.270595">
						<inertial pos="0 0 0" quat="0.5 0.5 -0.5 0.5" mass="0.3" diaginertia="0.000735 0.00039 0.00039" />
						<joint name="Stoupento__wheel_link1L" pos="0 0 0" axis="0 0 1"/>
						<geom size="0.07 0.015" type="cylinder" rgba="0.8 0 0 1" />
					</body>
				</body>
			</body>
			<body name="Stoupento__right_link4" pos="0.03831 0.125 0.38107" quat="-0.399517 1.74638e-06 0.916726 1.74638e-06">
				<inertial pos="-0.0965 0.005 0" quat="0.5 0.5 0.5 0.5" mass="0.1" diaginertia="0.000317908 0.000311242 8.33333e-06" />
				<joint name="Stoupento__link4_bodyR" pos="0 0 0" axis="0 1 0" />
				<geom size="0.0965 0.005 0.015" pos="-0.0965 0.005 0" type="box" rgba="0 0 0 1" />
			</body>
			<body name="Stoupento__left_link4" pos="0.03831 -0.125 0.38107" quat="-0.399517 1.74638e-06 0.916726 1.74638e-06">
				<inertial pos="-0.0965 -0.005 0" quat="0.5 0.5 0.5 0.5" mass="0.1" diaginertia="0.000317908 0.000311242 8.33333e-06" />
				<joint name="Stoupento__link4_bodyL" pos="0 0 0" axis="0 1 0" />
				<geom size="0.0965 0.005 0.015" pos="-0.0965 -0.005 0" type="box" rgba="0 0 0 1" />
			</body>
			<body name="imu_link" pos="0 0 0.45" euler="0 0 0">
				<!-- quat="0.7071 0 -0.7071 0" -->
				<!-- <camera name="camera_1" pos="0.2 0 0.1" euler="0 -1.57 1.57" /> -->
				<geom size="0.01 0.01 0.004" type="box" rgba="0 0 0 1" />
				<inertial pos="0 0 0" mass="0.001" diaginertia="0.0000000416667 0.0000000416667 0.0000000416667" />
				<joint name="imu_joint" pos="0 0 0" />
			</body>
		</body>
	</worldbody>

	<equality>
		<connect body2='Stoupento__left_link4' body1='Stoupento__left_link1' anchor='0 0 0' solref='0.005 1' />
		<connect body2='Stoupento__right_link4' body1='Stoupento__right_link1' anchor='0 0 0' solref='0.005 1' />
	</equality>

	<actuator>
		<!-- User parameter is the maximum no-load motor RPM -->
		<position name='left_hip' joint='Stoupento__link2_bodyL' gear='1' ctrllimited='true' ctrlrange='-0.2 0.3' kp="25" />
		<position name='right_hip' joint='Stoupento__link2_bodyR' gear='1' ctrllimited='true' ctrlrange='-0.2 0.3' kp="25" />
		<!-- <motor name='left_calf'   joint='left_calf_joint'   gear='16' ctrllimited='true' ctrlrange='-4.5 4.5'/>
        <motor name='right_calf'  joint='right_calf_joint'  gear='16' ctrllimited='true' ctrlrange='-4.5 4.5'/> -->
		<motor name='left_wheel' joint='Stoupento__wheel_link1L' gear='1' ctrllimited='true' ctrlrange='-1 1'/>
		<motor name='right_wheel' joint='Stoupento__wheel_link1R' gear='1' ctrllimited='true' ctrlrange='-1 1'/>
	</actuator>

	<sensor>
		<framequat name='imu' objtype='body' objname='imu_link' user="4" />
	</sensor>

</mujoco>